<robot name = "robot">
    <link name="Head">
        <inertial>
            <origin xyz="0 0 2" rpy="0 0 0" />
            <mass value="1" />
            <inertia ixx="100" ixy="0" ixz="0" iyy="100" iyz="0" izz="100" />
        </inertial>
        <visual>
            <origin xyz="0 0 2" rpy="0 0 0" />
            <geometry>
                <box size="0.3864708218359741 0.5337560021674903 0.674021724823386" />
            </geometry>
            <material name="Red">
                <color rgba="1 0 0 0.8"/>
            </material>
        </visual>
        <collision>
            <origin xyz="0 0 2" rpy="0 0 0" />
            <geometry>
                <box size="0.3864708218359741 0.5337560021674903 0.674021724823386" />
            </geometry>
        </collision>
    </link>
    <link name="Link3">
        <inertial>
            <origin xyz="0 0 0" rpy="0 0 0" />
            <mass value="1" />
            <inertia ixx="100" ixy="0" ixz="0" iyy="100" iyz="0" izz="100" />
        </inertial>
        <visual>
            <origin xyz="0 0 0" rpy="0 0 0" />
            <geometry>
                <box size="0.9479899368840365 0.6126082892961646 0.7888141097153907" />
            </geometry>
            <material name="Blue">
                <color rgba="0 0 1 0.8"/>
            </material>
        </visual>
        <collision>
            <origin xyz="0 0 0" rpy="0 0 0" />
            <geometry>
                <box size="0.9479899368840365 0.6126082892961646 0.7888141097153907" />
            </geometry>
        </collision>
    </link>
    <joint name="Head_Link3" type="revolute">
       <parent link="Head"/>
       <child  link="Link3"/>
       <origin rpy="0 0 0" xyz="-0.6672303793600053 0 2" />
       <axis xyz="1 0 0"/>
       <limit effort="100" lower="-3.14159" upper="3.14159" velocity="1.0"/>
    </joint>
    <link name="Link5">
        <inertial>
            <origin xyz="0 0 0" rpy="0 0 0" />
            <mass value="1" />
            <inertia ixx="100" ixy="0" ixz="0" iyy="100" iyz="0" izz="100" />
        </inertial>
        <visual>
            <origin xyz="0 0 0" rpy="0 0 0" />
            <geometry>
                <box size="0.8663498883909426 0.9915227057019984 0.7305531613538696" />
            </geometry>
            <material name="Green">
                <color rgba="0 1 0 0.8"/>
            </material>
        </visual>
        <collision>
            <origin xyz="0 0 0" rpy="0 0 0" />
            <geometry>
                <box size="0.8663498883909426 0.9915227057019984 0.7305531613538696" />
            </geometry>
        </collision>
    </link>
    <joint name="Head_Link5" type="revolute">
       <parent link="Head"/>
       <child  link="Link5"/>
       <origin rpy="0 0 0" xyz="0 0 1.2977125569113723" />
       <axis xyz="0 0 1"/>
       <limit effort="100" lower="-3.14159" upper="3.14159" velocity="1.0"/>
    </joint>
    <link name="Link6">
        <inertial>
            <origin xyz="0 0 0" rpy="0 0 0" />
            <mass value="1" />
            <inertia ixx="100" ixy="0" ixz="0" iyy="100" iyz="0" izz="100" />
        </inertial>
        <visual>
            <origin xyz="0 0 0" rpy="0 0 0" />
            <geometry>
                <box size="0.5164359340861798 0.3741932840445427 0.6166683211816208" />
            </geometry>
            <material name="Green">
                <color rgba="0 1 0 0.8"/>
            </material>
        </visual>
        <collision>
            <origin xyz="0 0 0" rpy="0 0 0" />
            <geometry>
                <box size="0.5164359340861798 0.3741932840445427 0.6166683211816208" />
            </geometry>
        </collision>
    </link>
    <joint name="Head_Link6" type="revolute">
       <parent link="Head"/>
       <child  link="Link6"/>
       <origin rpy="0 0 0" xyz="0 -0.45397464310601654 2" />
       <axis xyz="0 1 0"/>
       <limit effort="100" lower="-3.14159" upper="3.14159" velocity="1.0"/>
    </joint>
</robot>